Workbook
Name ProjFCFs: 'Master Data'!$K$21:$K$26
Name Slicer_Year: #N/A
Name t: 'Master Data'!$S$21:$S$26

Sheet Cover Page
A1: Stryker Corporation DCF Evaluation
A2: Harris Waseem
A3: BUS 341W & CSCI 48
A4: Luc Marest, Matthew Fried, Shu Yuan Wu | E4: Table of Contents
A5: March - May 9th, 2026 | D5: 1 | E5: =HYPERLINK("#'DCF Dashboard'!A2", "DCF Dashboard") -> DCF Dashboard
D6: 2 | E6: =HYPERLINK("#'WACC Dashboard'!A1", "WACC Dashboard") -> WACC Dashboard
D7: 3 | E7: =HYPERLINK("#'WACC PivotTable'!A1", "Stock Price Movement") -> Stock Price Movement
D8: 4 | E8: =HYPERLINK("#'Master Data'!A1", "Master Data") -> Master Data
D9: 5 | E9: =HYPERLINK("#'SYK'!A1", "Stryker Corporation Overview") -> Stryker Corporation Overview
E10: Competitors
D11: 6 | E11: =HYPERLINK("#'JNJ'!A1", "Johnson & Johnson OV") -> Johnson & Johnson OV
D12: 7 | E12: =HYPERLINK("#'ABBOTT'!A1","Abbott Laboratories OV") -> Abbott Laboratories OV
D13: 8 | E13: =HYPERLINK("#'BSX'!A1","Boston Scientific Corporation OV") -> Boston Scientific Corporation OV
D14: 9 | E14: =HYPERLINK("#'EDW'!A1","Edwards Lifesciences Corporation OV") -> Edwards Lifesciences Corporation OV

Sheet DCF Dashboard
A1: Simple Current Snapshot (2026 - 2027) | D1: Red Circle = Trading Hours are over | G1: =TODAY() -> 46160 | H1: =NOW()-TODAY() -> 0.63022176 | K1: Select below:
A2: In Millions USD | B2: Enterprise Value | C2: Net Debt | D2: Equity Value | E2: Diluted Shares | F2: Imp. Share Price | G2: Current Share Price | H2: Valuation | K2: Bloomberg | L2: =K2 & " Revenue & YoY Growth" -> Bloomberg Revenue & YoY Growth
B3: ='BBG Adj Highlights'!I10 -> 146697.27 | C3: ='Master Data'!M9 -> 9193.2857 | D3: ='WACC Dashboard'!B2 -> 134437.3 | E3: =SYK!L176 -> 386.5 | F3: =(B3-C3)/E3 -> 355.76711 | G3: {=IFERROR(_xlfn.STOCKHISTORY("SYK",$G$1,,,0,1),IFERROR(_xlfn.STOCKHISTORY("SYK",$G$1-1,,,0,1),IFERROR(_xlfn.STOCKHISTORY("SYK",$G$1-2,,,0,1),IFERROR(_xlfn.STOCKHISTORY("SYK",$G$1-3,,,0,1),0))))} -> 306.76 | H3: =G3/F3-1 -> -0.13775054 | K3: {=IF($K$2="Bloomberg",'Master Data'!A1:C10,'Master Data'!A13:C26)} -> Year | L3: Revenue Adj ($M) | M3: YoY Growth %
F4: Bloomberg Evaluation Approx. | K4: FY 2019 | L4: 14884 | M4: 0.094331
K5: FY 2020 | L5: 14351 | M5: -0.03581
B6: Enterprise Value | C6: Net Debt | D6: Equity Value | E6: Diluted Shares | F6: Imp. Share Price | G6: Current Share Price | H6: Valuation | K6: FY 2021 | L6: 17108 | M6: 0.192112
B7: ='Master Data'!L39 -> 91461.071 | C7: ='Master Data'!M21 -> 9193.2857 | D7: ='Master Data'!N39 -> 82267.785 | E7: 386.5 | F7: =(B7-C7)/E7 -> 212.85326 | G7: {=IFERROR(_xlfn.STOCKHISTORY("SYK",$G$1,,,0,1),IFERROR(_xlfn.STOCKHISTORY("SYK",$G$1-1,,,0,1),IFERROR(_xlfn.STOCKHISTORY("SYK",$G$1-2,,,0,1),IFERROR(_xlfn.STOCKHISTORY("SYK",$G$1-3,,,0,1),0))))} -> 306.76 | H7: =G7/F7-1 -> 0.44118065 | K7: FY 2022 | L7: 18449 | M7: 0.078384
F8: Quick Personal Evaluation Approx. | K8: FY 2023 | L8: 20498 | M8: 0.111063
A9: Simple Forward Snapshot (2027) | K9: FY 2024 | L9: 22595 | M9: 0.102303
A10: In Millions USD | B10: Enterprise Value | C10: Net Debt | D10: Equity Value | E10: Diluted Shares | F10: Imp. Share Price | G10: Current Share Price | H10: Valuation | K10: FY 2025 | L10: 25116 | M10: 0.111573
B11: ='Master Data'!L40 -> 94204.903 | C11: ='Master Data'!M22 -> 5874.5714 | D11: ='Master Data'!N40 -> 85011.617 | E11: 386.5 | F11: =(B11-C11)/E11 -> 228.53902 | G11: {=IFERROR(_xlfn.STOCKHISTORY("SYK",$G$1,,,0,1),IFERROR(_xlfn.STOCKHISTORY("SYK",$G$1-1,,,0,1),IFERROR(_xlfn.STOCKHISTORY("SYK",$G$1-2,,,0,1),IFERROR(_xlfn.STOCKHISTORY("SYK",$G$1-3,,,0,1),0))))} -> 306.76 | H11: =G11/F11-1 -> 0.34226531 | K11: FY 2026 | L11: 27317.214 | M11: 0.087641913
F12: Quick Personal Future Evaluation Approx. | K12: FY 2027 | L12: 29602.893 | M12: 0.08367173
A15: Advanced Forward Snapshot (2026 - 2031)
A16: In Millions USD | B16: Enterprise Value | C16: Net Debt | D16: Equity Value | E16: Diluted Shares | F16: Imp. Share Price | G16: Current Share Price | H16: Valuation
B17: ='Master Data'!L33 -> 118366.12 | C17: ='Master Data'!M21 -> 9193.2857 | D17: =B17-C17 -> 109172.83 | E17: 386.5 | F17: =(B17-C17)/E17 -> 282.46528 | G17: =INDEX(F2:H17,2,2) -> 306.76 | H17: =G17/F17-1 -> 0.086009583
F18: In-depth Personal Future Evaluation Approx.
A20: Sensitivity Analysis (2026 - 2031)
A21: WACC / Terminal
A22: =F17 -> 282.46528 | B22: 0.02 | C22: 0.025 | D22: 0.03 | E22: 0.035 | F22: 0.04 | G22: 0.045
A23: 0.075 | B23: 243.68155 | C23: 259.86489 | D23: 278.85893 | E23: 301.46551 | F23: 328.82357 | G23: 362.60703
A24: 0.08 | B24: 244.95013 | C24: 261.20939 | D24: 280.29253 | E24: 303.00515 | F24: 330.49155 | G24: 364.43349
A25: 0.085 | B25: 246.21871 | C25: 262.55389 | D25: 281.72613 | E25: 304.5448 | F25: 332.15953 | G25: 366.25995
A26: 0.0876 | B26: 246.87838 | C26: 263.25303 | D26: 282.4716 | E26: 305.34542 | F26: 333.02688 | G26: 367.20971
A27: 0.09 | B27: 247.4873 | C27: 263.89839 | D27: 283.15973 | E27: 306.08445 | F27: 333.82751 | G27: 368.08641
A28: 0.095 | B28: 248.75588 | C28: 265.24289 | D28: 284.59333 | E28: 307.62409 | F28: 335.4955 | G28: 369.91287
A29: 0.1 | B29: 250.02446 | C29: 266.58739 | D29: 286.02693 | E29: 309.16374 | F29: 337.16348 | G29: 371.73933
B31: WACC | C31: 0.087577961
B32: T-G | C32: 0.03

Sheet DCF PivotTable
A3: Row Labels | B3: Average of MedSurg % of Rev | C3: Average of Ortho % of Rev
A4: FY 2019 | B4: 0.44654364 | C4: 0.55345636
A5: FY 2020 | B5: 0.56940339 | C5: 0.43059661
A6: FY 2021 | B6: 0.58149258 | C6: 0.41850742
A7: FY 2022 | B7: 0.55751695 | C7: 0.44248305
A8: FY 2023 | B8: 0.59043851 | C8: 0.40956149
A9: FY 2024 | B9: 0.59337496 | C9: 0.40662504
A10: FY 2025 | B10: 0.59827395 | C10: 0.40172605
A15: Row Labels | B15: Average of EBITDA Margin % | C15: Average of YoY Growth % | D15: Average of CapEx % | E15: Average of NWC %
A16: FY 2019 | B16: 0.29259608 | C16: 0.094331 | D16: 0.04360387 | E16: 0.44732599
A17: FY 2020 | B17: 0.27656609 | C17: -0.03581 | D17: 0.033934917 | E17: 0.32513414
A18: FY 2021 | B18: 0.28559738 | C18: 0.192112 | D18: 0.030687398 | E18: 0.31961655
A19: FY 2022 | B19: 0.26581387 | C19: 0.078384 | D19: 0.031871646 | E19: 0.21529622
A20: FY 2023 | B20: 0.26929457 | C20: 0.111063 | D20: 0.028051517 | E20: 0.22426578
A21: FY 2024 | B21: 0.28023899 | C21: 0.102303 | D21: 0.033414472 | E21: 0.32002655
A22: FY 2025 | B22: 0.2894171 | C22: 0.111573 | D22: 0.030299411 | E22: 0.27715401
A23: FY 2026 | B23: 0.27729002 | C23: 0.087577961 | D23: 0.026896155 | E23: 0.23388512
A24: FY 2027 | B24: 0.28120777 | C24: 0.0837 | D24: 0.02782944 | E24: 0.24466004
A25: FY 2028 | B25: 0.28268081 | C25: 0.07 | D25: 0.027539011 | E25: 0.24526955
A26: FY 2029 | B26: 0.28820306 | C26: 0.06 | D26: 0.026563039 | E26: 0.25529314
A27: FY 2030 | B27: 0.28881887 | C27: 0.05 | D27: 0.025986674 | E27: 0.2514053
A28: FY 2031 | B28: 0.28807985 | C28: 0.03 | D28: 0.024202131 | E28: 0.24598012
A32: Row Labels | B32: Average of Net Debt ($M) | C32: Average of Equity ($M) | D32: Sum of Equity - Debt
A33: FY 2019 | B33: 6665 | C33: 78638.306 | D33: 71973.306
A34: FY 2020 | B34: 10967 | C34: 92184.279 | D34: 81217.279
A35: FY 2021 | B35: 9460 | C35: 100963 | D35: 91503
A36: FY 2022 | B36: 11120 | C36: 92620.452 | D36: 81500.452
A37: FY 2023 | B37: 9942 | C37: 113873.87 | D37: 103931.87
A38: FY 2024 | B38: 9104 | C38: 137323.07 | D38: 128219.07
A39: FY 2025 | B39: 11759 | C39: 134437.27 | D39: 122678.27

Sheet Master Data
A1: Year | B1: Revenue Adj ($M) | C1: YoY Growth % | D1: Gross Margin % | E1: EBITDA Adj ($M) | F1: EBITDA Margin % | G1: EBIT ($M) | H1: NOPAT ($M) | I1: Net Income Adj ($M) | J1: Adj EPS | K1: FCF ($M) | L1: EV ($M) | M1: Net Debt ($M) | N1: Equity ($M) | O1: MedSurg % of Rev | P1: Ortho % of Rev | Q1: Rule of 40
A2: FY 2019 | B2: =_xlfn.XLOOKUP("*"&A2&"*",'BBG Adj Highlights'!$C$4:$L$4,'BBG Adj Highlights'!$C$12:$L$12, , 2) -> 14884 | C2: =_xlfn.XLOOKUP("*"&A2&"*",'BBG Adj Highlights'!$C$4:$L$4,'BBG Adj Highlights'!$C$13:$L$13, , 2)/100 -> 0.094331 | D2: =_xlfn.XLOOKUP("*"&RIGHT(A2,4)&"*", SYK!$E$3:$N$3, SYK!$E$27:$N$27,,2)/100 -> 0.659 | E2: =_xlfn.XLOOKUP("*"&A2&"*",'BBG Adj Highlights'!$C$4:$L$4,'BBG Adj Highlights'!$C$16:$L$16,,2) -> 4355 | F2: =_xlfn.XLOOKUP("*"&A2&"*",'BBG Adj Highlights'!$C$4:$L$4,'BBG Adj Highlights'!$C$17:$L$17,,2) /100 -> 0.29259608 | G2: =_xlfn.XLOOKUP("*"&A2&"*",'BBG Adjusted'!$C$4:$L$4,'BBG Adjusted'!$C$65:$L$65,,2) -> 3444 | I2: =_xlfn.XLOOKUP("*"&A2&"*",'BBG Adj Highlights'!$C$4:$L$4,'BBG Adj Highlights'!$C$18:$L$18,,2) -> 2764 | J2: =_xlfn.XLOOKUP("*"&A2&"*",'BBG Adj Highlights'!$C$4:$L$4,'BBG Adj Highlights'!$C$20:$L$20,,2) -> 7.2726 | K2: =_xlfn.XLOOKUP("*"&A2&"*",'BBG Adj Highlights'!$C$4:$L$4,'BBG Adj Highlights'!$C$25:$L$25,,2) -> 1542 | L2: =_xlfn.XLOOKUP("*"&A2&"*",'BBG Adj Highlights'!$C$4:$L$4,'BBG Adj Highlights'!$C$10:$L$10,,2) -> 85690.306 | M2: =_xlfn.XLOOKUP("*"&RIGHT(A2,4)&"*", SYK!$E$3:$N$3, SYK!$E$31:$N$31,,2) -> 6665 | N2: =_xlfn.XLOOKUP("*"&A2&"*",'BBG Adj Highlights'!$C$4:$L$4,'BBG Adj Highlights'!$C$6:$L$6, , 2) -> 78638.306 | O2: =_xlfn.XLOOKUP("*"&A2&"*",Segments!$E$3:$N$3,Segments!$E$7:$N$7,,2)/100 -> 0.44654364 | P2: =1-O2 -> 0.55345636 | Q2: =SUM(C2,F2) -> 0.38692708
A3: FY 2020 | B3: 14351 | C3: -0.03581 | D3: 0.638 | E3: 3969 | F3: 0.27656609 | G3: 3027 | I3: 2446 | J3: 6.4272 | K3: 2790 | L3: 103585.28 | M3: =_xlfn.XLOOKUP("*"&RIGHT(A3,4)&"*", SYK!$E$3:$N$3, SYK!$E$31:$N$31,,2) -> 10967 | N3: 92184.279 | O3: 0.56940339 | P3: 0.43059661 | Q3: =SUM(C3,F3) -> 0.24075609
A4: FY 2021 | B4: 17108 | C4: 0.192112 | D4: 0.641 | E4: 4886 | F4: 0.28559738 | G4: 3763 | I4: 2985 | J4: 7.8022 | K4: 2738 | L4: 110845 | M4: =_xlfn.XLOOKUP("*"&RIGHT(A4,4)&"*", SYK!$E$3:$N$3, SYK!$E$31:$N$31,,2) -> 9460 | N4: 100963 | O4: 0.58149258 | P4: 0.41850742 | Q4: =SUM(C4,F4) -> 0.47770938
A5: FY 2022 | B5: 18449 | C5: 0.078384 | D5: 0.631 | E5: 4904 | F5: 0.26581387 | G5: 3757 | I5: 3076 | J5: 8.0486 | K5: 2036 | L5: 104218.45 | M5: =_xlfn.XLOOKUP("*"&RIGHT(A5,4)&"*", SYK!$E$3:$N$3, SYK!$E$31:$N$31,,2) -> 11120 | N5: 92620.452 | O5: 0.55751695 | P5: 0.44248305 | Q5: =SUM(C5,F5) -> 0.34419787
A6: FY 2023 | B6: 20498 | C6: 0.111063 | D6: 0.639 | E6: 5520 | F6: 0.26929457 | G6: 4320 | I6: 3563 | J6: 9.2873 | K6: 3136 | L6: 124314.87 | M6: =_xlfn.XLOOKUP("*"&RIGHT(A6,4)&"*", SYK!$E$3:$N$3, SYK!$E$31:$N$31,,2) -> 9942 | N6: 113873.87 | O6: 0.59043851 | P6: 0.40956149 | Q6: =SUM(C6,F6) -> 0.38035757
A7: FY 2024 | B7: 22595 | C7: 0.102303 | D7: 0.64461164 | E7: 6332 | F7: 0.28023899 | G7: 5092 | I7: 4205 | J7: 10.9032 | K7: 3487 | L7: 146950.07 | M7: =_xlfn.XLOOKUP("*"&RIGHT(A7,4)&"*", SYK!$E$3:$N$3, SYK!$E$31:$N$31,,2) -> 9104 | N7: 137323.07 | O7: 0.59337496 | P7: 0.40662504 | Q7: =SUM(C7,F7) -> 0.38254199
A8: FY 2025 | B8: 25116 | C8: 0.111573 | D8: 0.653 | E8: 7269 | F8: 0.2894171 | G8: 5871 | I8: 4686 | J8: 12.1257 | K8: 4283 | L8: 146697.27 | M8: =_xlfn.XLOOKUP("*"&RIGHT(A8,4)&"*", SYK!$E$3:$N$3, SYK!$E$31:$N$31,,2) -> 11759 | N8: 134437.27 | O8: 0.59827395 | P8: 0.40172605 | Q8: =SUM(C8,F8) -> 0.4009901
A9: FY 2026 | B9: =_xlfn.XLOOKUP("*"&A9&"*",'BBG Adj Highlights'!$C$4:$L$4,'BBG Adj Highlights'!$C$12:$L$12, , 2) -> 27317.214 | C9: =_xlfn.XLOOKUP("*"&A9&"*",'BBG Adj Highlights'!$C$4:$L$4,'BBG Adj Highlights'!$C$13:$L$13, , 2)/100 -> 0.087641913 | D9: =_xlfn.XLOOKUP("*"&RIGHT(A9,4)&"*", SYK!$E$3:$N$3, SYK!$E$27:$N$27,,2)/100 -> 0.65211765 | E9: =_xlfn.XLOOKUP("*"&A9&"*",'BBG Adj Highlights'!$C$4:$L$4,'BBG Adj Highlights'!$C$16:$L$16,,2) -> 7838.9167 | F9: =_xlfn.XLOOKUP("*"&A9&"*",'BBG Adj Highlights'!$C$4:$L$4,'BBG Adj Highlights'!$C$17:$L$17,,2) /100 -> 0.28695886 | G9: =_xlfn.XLOOKUP("*"&A9&"*",'BBG Adjusted'!$C$4:$L$4,'BBG Adjusted'!$C$65:$L$65,,2) -> 7296.6923 | I9: =_xlfn.XLOOKUP("*"&A9&"*",'BBG Adj Highlights'!$C$4:$L$4,'BBG Adj Highlights'!$C$18:$L$18,,2) -> 5814.833 | J9: =_xlfn.XLOOKUP("*"&A9&"*",'BBG Adj Highlights'!$C$4:$L$4,'BBG Adj Highlights'!$C$20:$L$20,,2) -> 15.013 | K9: =_xlfn.XLOOKUP("*"&A9&"*",'BBG Adj Highlights'!$C$4:$L$4,'BBG Adj Highlights'!$C$25:$L$25,,2) -> 5415.525 | L9: =_xlfn.XLOOKUP("*"&A9&"*",'BBG Adj Highlights'!$C$4:$L$4,'BBG Adj Highlights'!$C$10:$L$10,,2) -> 0 | M9: =_xlfn.XLOOKUP("*"&RIGHT(A9,4)&"*", SYK!$E$3:$N$3, SYK!$E$31:$N$31,,2) -> 9193.2857 | N9: =_xlfn.XLOOKUP("*"&A9&"*",'BBG Adj Highlights'!$C$4:$L$4,'BBG Adj Highlights'!$C$6:$L$6, , 2) -> 0 | O9: =IFERROR(_xlfn.XLOOKUP("*"&A9&"*",Segments!$E$3:$N$3,Segments!$E$7:$N$7,,2)/100,0) -> 0 | P9: =IFERROR(_xlfn.XLOOKUP("*"&A9&"*",Segments!$E$3:$N$3,Segments!$E$21:$N$21,,2)/100,0) -> 0 | Q9: =SUM(C9,F9) -> 0.37460077
A10: FY 2027 | B10: =_xlfn.XLOOKUP("*"&A10&"*",'BBG Adj Highlights'!$C$4:$L$4,'BBG Adj Highlights'!$C$12:$L$12, , 2) -> 29602.893 | C10: =_xlfn.XLOOKUP("*"&A10&"*",'BBG Adj Highlights'!$C$4:$L$4,'BBG Adj Highlights'!$C$13:$L$13, , 2)/100 -> 0.08367173 | D10: =_xlfn.XLOOKUP("*"&RIGHT(A10,4)&"*", SYK!$E$3:$N$3, SYK!$E$27:$N$27,,2)/100 -> 0.6546326 | E10: =_xlfn.XLOOKUP("*"&A10&"*",'BBG Adj Highlights'!$C$4:$L$4,'BBG Adj Highlights'!$C$16:$L$16,,2) -> 8626.3478 | F10: =_xlfn.XLOOKUP("*"&A10&"*",'BBG Adj Highlights'!$C$4:$L$4,'BBG Adj Highlights'!$C$17:$L$17,,2) /100 -> 0.29140219 | G10: =_xlfn.XLOOKUP("*"&A10&"*",'BBG Adjusted'!$C$4:$L$4,'BBG Adjusted'!$C$65:$L$65,,2) -> 8076.7692 | I10: =_xlfn.XLOOKUP("*"&A10&"*",'BBG Adj Highlights'!$C$4:$L$4,'BBG Adj Highlights'!$C$18:$L$18,,2) -> 6484.64 | J10: =_xlfn.XLOOKUP("*"&A10&"*",'BBG Adj Highlights'!$C$4:$L$4,'BBG Adj Highlights'!$C$20:$L$20,,2) -> 16.746 | K10: =_xlfn.XLOOKUP("*"&A10&"*",'BBG Adj Highlights'!$C$4:$L$4,'BBG Adj Highlights'!$C$25:$L$25,,2) -> 5637.65 | L10: =_xlfn.XLOOKUP("*"&A10&"*",'BBG Adj Highlights'!$C$4:$L$4,'BBG Adj Highlights'!$C$10:$L$10,,2) -> 0 | M10: =_xlfn.XLOOKUP("*"&RIGHT(A10,4)&"*", SYK!$E$3:$N$3, SYK!$E$31:$N$31,,2) -> 5874.5714 | N10: =_xlfn.XLOOKUP("*"&A10&"*",'BBG Adj Highlights'!$C$4:$L$4,'BBG Adj Highlights'!$C$6:$L$6, , 2) -> 0 | O10: =IFERROR(_xlfn.XLOOKUP("*"&A10&"*",Segments!$E$3:$N$3,Segments!$E$7:$N$7,,2)/100,0) -> 0 | P10: =IFERROR(_xlfn.XLOOKUP("*"&A10&"*",Segments!$E$3:$N$3,Segments!$E$21:$N$21,,2)/100,0) -> 0 | Q10: =SUM(C10,F10) -> 0.37507392
M11: Extracted Bloomberg Valuations
A13: Year | B13: Revenue Adj ($M) | C13: YoY Growth % | D13: Gross Margin % | E13: EBITDA Adj ($M) | F13: EBITDA Margin % | G13: EBIT ($M) | H13: NOPAT ($M) | I13: Net Income Adj ($M) | J13: Adj EPS | K13: FCF ($M) | L13: EV ($M) | M13: Net Debt ($M) | N13: Equity ($M) | O13: CapEx % | P13: NWC ($M) | Q13: NWC % | R13: ∆ NWC
A14: FY 2019 | B14: 14884 | C14: 0.094331 | D14: 0.659 | E14: 4355 | F14: 0.29259608 | G14: =_xlfn.XLOOKUP("*"&A14&"*",'BBG Adjusted'!$C$4:$L$4,'BBG Adjusted'!$C$65:$L$65,,2) -> 3444 | I14: 2764 | J14: 7.2726 | K14: 1542 | L14: 85690.306 | M14: 6665 | N14: =_xlfn.XLOOKUP("*"&A14&"*",'BBG Adj Highlights'!$C$4:$L$4,'BBG Adj Highlights'!$C$6:$L$6, , 2) -> 78638.306 | O14: =_xlfn.XLOOKUP("*"&RIGHT(A2,4)&"*",SYK!$E$3:$N$3,SYK!$E$276:$N$276,,2) / 100 -> 0.04360387 | P14: =_xlfn.XLOOKUP("*"&RIGHT(A14,4)&"*", SYK!$E$3:$N$3, SYK!$E$203:$N$203,,2)-_xlfn.XLOOKUP("*"&RIGHT(A14,4)&"*", SYK!$E$3:$N$3, SYK!$E$222:$N$222,,2) -> 6658 | Q14: =P14/B14 -> 0.44732599
A15: FY 2020 | B15: 14351 | C15: -0.03581 | D15: 0.638 | E15: 3969 | F15: 0.27656609 | G15: 3027 | I15: 2446 | J15: 6.4272 | K15: 2790 | L15: 103585.28 | M15: 10967 | N15: =_xlfn.XLOOKUP("*"&A15&"*",'BBG Adj Highlights'!$C$4:$L$4,'BBG Adj Highlights'!$C$6:$L$6, , 2) -> 92184.279 | O15: =_xlfn.XLOOKUP("*"&RIGHT(A3,4)&"*",SYK!$E$3:$N$3,SYK!$E$276:$N$276,,2) / 100 -> 0.033934917 | P15: =_xlfn.XLOOKUP("*"&RIGHT(A15,4)&"*", SYK!$E$3:$N$3, SYK!$E$203:$N$203,,2)-_xlfn.XLOOKUP("*"&RIGHT(A15,4)&"*", SYK!$E$3:$N$3, SYK!$E$222:$N$222,,2) -> 4666 | Q15: =P15/B15 -> 0.32513414 | R15: =P15-P14 -> -1992
A16: FY 2021 | B16: 17108 | C16: 0.192112 | D16: 0.641 | E16: 4886 | F16: 0.28559738 | G16: 3763 | I16: 2985 | J16: 7.8022 | K16: 2738 | L16: 110845 | M16: 9460 | N16: 100963 | O16: =_xlfn.XLOOKUP("*"&RIGHT(A4,4)&"*",SYK!$E$3:$N$3,SYK!$E$276:$N$276,,2) / 100 -> 0.030687398 | P16: =_xlfn.XLOOKUP("*"&RIGHT(A16,4)&"*", SYK!$E$3:$N$3, SYK!$E$203:$N$203,,2)-_xlfn.XLOOKUP("*"&RIGHT(A16,4)&"*", SYK!$E$3:$N$3, SYK!$E$222:$N$222,,2) -> 5468 | Q16: =P16/B16 -> 0.31961655 | R16: =P16-P15 -> 802
A17: FY 2022 | B17: 18449 | C17: 0.078384 | D17: 0.631 | E17: 4904 | F17: 0.26581387 | G17: 3757 | I17: 3076 | J17: 8.0486 | K17: 2036 | L17: 104218.45 | M17: 11120 | N17: 92620.452 | O17: =_xlfn.XLOOKUP("*"&RIGHT(A5,4)&"*",SYK!$E$3:$N$3,SYK!$E$276:$N$276,,2) / 100 -> 0.031871646 | P17: =_xlfn.XLOOKUP("*"&RIGHT(A17,4)&"*", SYK!$E$3:$N$3, SYK!$E$203:$N$203,,2)-_xlfn.XLOOKUP("*"&RIGHT(A17,4)&"*", SYK!$E$3:$N$3, SYK!$E$222:$N$222,,2) -> 3972 | Q17: =P17/B17 -> 0.21529622 | R17: =P17-P16 -> -1496
A18: FY 2023 | B18: 20498 | C18: 0.111063 | D18: 0.639 | E18: 5520 | F18: 0.26929457 | G18: 4320 | I18: 3563 | J18: 9.2873 | K18: 3136 | L18: 124314.87 | M18: 9942 | N18: 113873.87 | O18: =_xlfn.XLOOKUP("*"&RIGHT(A6,4)&"*",SYK!$E$3:$N$3,SYK!$E$276:$N$276,,2) / 100 -> 0.028051517 | P18: =_xlfn.XLOOKUP("*"&RIGHT(A18,4)&"*", SYK!$E$3:$N$3, SYK!$E$203:$N$203,,2)-_xlfn.XLOOKUP("*"&RIGHT(A18,4)&"*", SYK!$E$3:$N$3, SYK!$E$222:$N$222,,2) -> 4597 | Q18: =P18/B18 -> 0.22426578 | R18: =P18-P17 -> 625
A19: FY 2024 | B19: 22595 | C19: 0.102303 | D19: 0.64461164 | E19: 6332 | F19: 0.28023899 | G19: 5092 | I19: 4205 | J19: 10.9032 | K19: 3487 | L19: 146950.07 | M19: 9104 | N19: 137323.07 | O19: =_xlfn.XLOOKUP("*"&RIGHT(A7,4)&"*",SYK!$E$3:$N$3,SYK!$E$276:$N$276,,2) / 100 -> 0.033414472 | P19: =_xlfn.XLOOKUP("*"&RIGHT(A19,4)&"*", SYK!$E$3:$N$3, SYK!$E$203:$N$203,,2)-_xlfn.XLOOKUP("*"&RIGHT(A19,4)&"*", SYK!$E$3:$N$3, SYK!$E$222:$N$222,,2) -> 7231 | Q19: =P19/B19 -> 0.32002655 | R19: =P19-P18 -> 2634
A20: FY 2025 | B20: 25116 | C20: 0.111573 | D20: 0.653 | E20: 7269 | F20: 0.2894171 | G20: 5871 | I20: 4686 | J20: 12.1257 | K20: 4283 | L20: 146697.27 | M20: 11759 | N20: 134437.27 | O20: =_xlfn.XLOOKUP("*"&RIGHT(A8,4)&"*",SYK!$E$3:$N$3,SYK!$E$276:$N$276,,2) / 100 -> 0.030299411 | P20: =_xlfn.XLOOKUP("*"&RIGHT(A20,4)&"*", SYK!$E$3:$N$3, SYK!$E$203:$N$203,,2)-_xlfn.XLOOKUP("*"&RIGHT(A20,4)&"*", SYK!$E$3:$N$3, SYK!$E$222:$N$222,,2) -> 6961 | Q20: =P20/B20 -> 0.27715401 | R20: =P20-P19 -> -270
A21: FY 2026 | B21: =B20*(1+'DCF Dashboard'!C31) -> 27315.608 | C21: ='WACC Dashboard'!B16 -> 0.087577961 | E21: =B21*F21 -> 7574.3455 | F21: {=TREND(F14:F20,(VALUE(RIGHT(A14:A20,4))),VALUE(RIGHT(A21,4)))} -> 0.27729002 | G21: =E21-(B21*0.045) -> 6345.1431 | H21: =G21*(1-15.5%) -> 5361.646 | K21: =H21+(B21*0.045)-(B21*O21)-R21 -> 6428.4492 | M21: 9193.2857 | O21: {=TREND(O14:O20,(VALUE(RIGHT(A14:A20,4))),VALUE(RIGHT(A21,4)))} -> 0.026896155 | P21: {=TREND(P14:P20,(VALUE(RIGHT(A14:A20,4))),VALUE(RIGHT(A21,4)))} -> 6388.7143 | Q21: =P21/B21 -> 0.23388512 | R21: =P21-P20 -> -572.28571 | S21: 1
A22: FY 2027 | B22: =B21*(1+C22) -> 29601.924 | C22: 0.0837 | E22: =B22*F22 -> 8324.2911 | F22: {=TREND(F15:F21,(VALUE(RIGHT(A15:A21,4))),VALUE(RIGHT(A22,4)))} -> 0.28120777 | G22: =E22-(B22*0.045) -> 6992.2045 | H22: =G22*(1-15.5%) -> 5908.4128 | K22: =H22+(B22*0.045)-(B22*O22)-R22 -> 5563.0005 | M22: 5874.5714 | O22: {=TREND(O15:O21,(VALUE(RIGHT(A15:A21,4))),VALUE(RIGHT(A22,4)))} -> 0.02782944 | P22: {=TREND(P15:P21,(VALUE(RIGHT(A15:A21,4))),VALUE(RIGHT(A22,4)))} -> 7242.4082 | Q22: =P22/B22 -> 0.24466004 | R22: =P22-P21 -> 853.69388 | S22: 2
A23: FY 2028 | B23: =B22*(1+C23) -> 31674.059 | C23: 0.07 | E23: =B23*F23 -> 8953.6489 | F23: {=TREND(F16:F22,(VALUE(RIGHT(A16:A22,4))),VALUE(RIGHT(A23,4)))} -> 0.28268081 | G23: =E23-(B23*0.045) -> 7528.3162 | H23: =G23*(1-15.5%) -> 6361.4272 | K23: =H23+(B23*0.045)-(B23*O23)-R23 -> 6388.2135 | O23: {=TREND(O16:O22,(VALUE(RIGHT(A16:A22,4))),VALUE(RIGHT(A23,4)))} -> 0.027539011 | P23: {=TREND(P16:P22,(VALUE(RIGHT(A16:A22,4))),VALUE(RIGHT(A23,4)))} -> 7768.6822 | Q23: =P23/B23 -> 0.24526955 | R23: =P23-P22 -> 526.27405 | S23: 3
A24: FY 2029 | B24: =B23*(1+C24) -> 33574.503 | C24: 0.06 | E24: =B24*F24 -> 9676.2744 | F24: {=TREND(F17:F23,(VALUE(RIGHT(A17:A23,4))),VALUE(RIGHT(A24,4)))} -> 0.28820306 | G24: =E24-(B24*0.045) -> 8165.4218 | H24: =G24*(1-15.5%) -> 6899.7814 | K24: =H24+(B24*0.045)-(B24*O24)-R24 -> 6716.1351 | O24: {=TREND(O17:O23,(VALUE(RIGHT(A17:A23,4))),VALUE(RIGHT(A24,4)))} -> 0.026563039 | P24: {=TREND(P17:P23,(VALUE(RIGHT(A17:A23,4))),VALUE(RIGHT(A24,4)))} -> 8571.3403 | Q24: =P24/B24 -> 0.25529314 | R24: =P24-P23 -> 802.65806 | S24: 4
A25: FY 2030 | B25: =B24*(1+C25) -> 35253.228 | C25: 0.05 | E25: =B25*F25 -> 10181.798 | F25: {=TREND(F18:F24,(VALUE(RIGHT(A18:A24,4))),VALUE(RIGHT(A25,4)))} -> 0.28881887 | G25: =E25-(B25*0.045) -> 8595.4023 | H25: =G25*(1-15.5%) -> 7263.1149 | K25: =H25+(B25*0.045)-(B25*O25)-R25 -> 7641.888 | O25: {=TREND(O18:O24,(VALUE(RIGHT(A18:A24,4))),VALUE(RIGHT(A25,4)))} -> 0.025986674 | P25: {=TREND(P18:P24,(VALUE(RIGHT(A18:A24,4))),VALUE(RIGHT(A25,4)))} -> 8862.8483 | Q25: =P25/B25 -> 0.2514053 | R25: =P25-P24 -> 291.50806 | S25: 5
A26: FY 2031 | B26: =B25*(1+C26) -> 36310.825 | C26: 0.03 | E26: =B26*F26 -> 10460.417 | F26: {=TREND(F19:F25,(VALUE(RIGHT(A19:A25,4))),VALUE(RIGHT(A26,4)))} -> 0.28807985 | G26: =E26-(B26*0.045) -> 8826.43 | H26: =G26*(1-15.5%) -> 7458.3333 | K26: =H26+(B26*0.045)-(B26*O26)-R26 -> 8144.6285 | O26: {=TREND(O19:O25,(VALUE(RIGHT(A19:A25,4))),VALUE(RIGHT(A26,4)))} -> 0.024202131 | P26: {=TREND(P19:P25,(VALUE(RIGHT(A19:A25,4))),VALUE(RIGHT(A26,4)))} -> 8931.741 | Q26: =P26/B26 -> 0.24598012 | R26: =P26-P25 -> 68.89263 | S26: 6
K27: PVs ($M) | L27: EV ($M) | M27: Personal DCF Valuation
J28: FY 2026 | K28: {=ProjFCFs/(1+'WACC Dashboard'!B16)^t} -> 5910.7939
J29: FY 2027 | K29: 4703.1443
J30: FY 2028 | K30: 4965.903
J31: FY 2029 | K31: 4800.4045
J32: FY 2030 | K32: 5022.254
J33: FY 2031 | K33: 4921.6292 | L33: =SUM(K28:K32)+(K34/(1+'WACC Dashboard'!B16)^5) -> 118366.12
J34: TV ($M) | K34: =K26/('WACC Dashboard'!B16-'DCF Dashboard'!C32) -> 141453.92
K38: FCF ($M) | L38: EV ($M) | N38: Equity ($M) | Q38: TVs ($M) | R38: PV(TVs) ($M) | S38: PV(FCF) ($M)
J39: FY 2026 | K39: 5415.525 | L39: =R39+S39 -> 91461.071 | N39: =L39-'DCF Dashboard'!C3 -> 82267.785 | Q39: =K39/('WACC Dashboard'!B16-'Master Data'!O46) -> 94055.52 | R39: =Q39/(1+'WACC Dashboard'!B16) -> 86481.635 | S39: =K39/(1+'WACC Dashboard'!B16) -> 4979.4361
J40: FY 2027 | K40: =K39*(1+O46) -> 5577.9907 | L40: =R40+S40 -> 94204.903 | N40: =L40-'DCF Dashboard'!C3 -> 85011.617 | Q40: =K40/('WACC Dashboard'!B16-'Master Data'!O46) -> 96877.185 | R40: =Q40/(1+'WACC Dashboard'!B16) -> 89076.084 | S40: =K40/(1+'WACC Dashboard'!B16) -> 5128.8192
K41: Manually Calc'd WACC & 3% Terminal Growth
O42: 0.08
O43: 0.07
O44: 0.06
...

Sheet Summary Statistics
A1: Year | B1: Revenue Adj ($M) | C1: YoY Growth % | D1: Gross Margin % | E1: EBITDA Adj ($M) | F1: EBITDA Margin % | G1: EBIT ($M) | H1: Net Income Adj ($M) | I1: Adj EPS | J1: FCF ($M) | K1: EV ($M) | L1: Net Debt ($M) | M1: Equity ($M) | N1: MedSurg % of Rev | O1: Ortho % of Rev | P1: Rule of 40 | R1: Advanced Filter | S1: Year | T1: Revenue Adj ($M) | U1: YoY Growth % | V1: EBITDA Adj ($M) | W1: EBITDA Margin % | X1: Adj EPS | Y1: FCF ($M) | Z1: Net Debt ($M) | AA1: Equity ($M)
A2: FY 2019 | B2: =_xlfn.XLOOKUP("*"&A2&"*",'BBG Adj Highlights'!$C$4:$L$4,'BBG Adj Highlights'!$C$12:$L$12, , 2) -> 14884 | C2: =_xlfn.XLOOKUP("*"&A2&"*",'BBG Adj Highlights'!$C$4:$L$4,'BBG Adj Highlights'!$C$13:$L$13, , 2)/100 -> 0.094331 | D2: =_xlfn.XLOOKUP("*"&RIGHT(A2,4)&"*", SYK!$E$3:$N$3, SYK!$E$27:$N$27,,2)/100 -> 0.659 | E2: =_xlfn.XLOOKUP("*"&A2&"*",'BBG Adj Highlights'!$C$4:$L$4,'BBG Adj Highlights'!$C$16:$L$16,,2) -> 4355 | F2: =_xlfn.XLOOKUP("*"&A2&"*",'BBG Adj Highlights'!$C$4:$L$4,'BBG Adj Highlights'!$C$17:$L$17,,2) /100 -> 0.29259608 | G2: =_xlfn.XLOOKUP("*"&A2&"*",'BBG Adjusted'!$C$4:$L$4,'BBG Adjusted'!$C$65:$L$65,,2) -> 3444 | H2: =_xlfn.XLOOKUP("*"&A2&"*",'BBG Adj Highlights'!$C$4:$L$4,'BBG Adj Highlights'!$C$18:$L$18,,2) -> 2764 | I2: =_xlfn.XLOOKUP("*"&A2&"*",'BBG Adj Highlights'!$C$4:$L$4,'BBG Adj Highlights'!$C$20:$L$20,,2) -> 7.2726 | J2: =_xlfn.XLOOKUP("*"&A2&"*",'BBG Adj Highlights'!$C$4:$L$4,'BBG Adj Highlights'!$C$25:$L$25,,2) -> 1542 | K2: =_xlfn.XLOOKUP("*"&A2&"*",'BBG Adj Highlights'!$C$4:$L$4,'BBG Adj Highlights'!$C$10:$L$10,,2) -> 85690.306 | L2: =_xlfn.XLOOKUP("*"&RIGHT(A2,4)&"*", SYK!$E$3:$N$3, SYK!$E$31:$N$31,,2) -> 6665 | M2: =_xlfn.XLOOKUP("*"&A2&"*",'BBG Adj Highlights'!$C$4:$L$4,'BBG Adj Highlights'!$C$6:$L$6, , 2) -> 78638.306 | N2: =_xlfn.XLOOKUP("*"&A2&"*",Segments!$E$3:$N$3,Segments!$E$7:$N$7,,2)/100 -> 0.44654364 | O2: =1-N2 -> 0.55345636 | P2: =SUM(C2,F2) -> 0.38692708 | S2: FY 2019 | T2: 14884 | U2: 0.094331 | V2: 4355 | W2: 0.29259608 | X2: 7.2726 | Y2: 1542 | Z2: 6665 | AA2: 78638.306
A3: FY 2020 | B3: 14351 | C3: -0.03581 | D3: 0.638 | E3: 3969 | F3: 0.27656609 | G3: 3027 | H3: 2446 | I3: 6.4272 | J3: 2790 | K3: 103585.28 | L3: =_xlfn.XLOOKUP("*"&RIGHT(A3,4)&"*", SYK!$E$3:$N$3, SYK!$E$31:$N$31,,2) -> 10967 | M3: 92184.279 | N3: 0.56940339 | O3: 0.43059661 | P3: =SUM(C3,F3) -> 0.24075609 | S3: FY 2020 | T3: 14351 | U3: -0.03581 | V3: 3969 | W3: 0.27656609 | X3: 6.4272 | Y3: 2790 | Z3: 10967 | AA3: 92184.279
A4: FY 2021 | B4: 17108 | C4: 0.192112 | D4: 0.641 | E4: 4886 | F4: 0.28559738 | G4: 3763 | H4: 2985 | I4: 7.8022 | J4: 2738 | K4: 110845 | L4: =_xlfn.XLOOKUP("*"&RIGHT(A4,4)&"*", SYK!$E$3:$N$3, SYK!$E$31:$N$31,,2) -> 9460 | M4: 100963 | N4: 0.58149258 | O4: 0.41850742 | P4: =SUM(C4,F4) -> 0.47770938 | S4: FY 2021 | T4: 17108 | U4: 0.192112 | V4: 4886 | W4: 0.28559738 | X4: 7.8022 | Y4: 2738 | Z4: 9460 | AA4: 100963
A5: FY 2022 | B5: 18449 | C5: 0.078384 | D5: 0.631 | E5: 4904 | F5: 0.26581387 | G5: 3757 | H5: 3076 | I5: 8.0486 | J5: 2036 | K5: 104218.45 | L5: =_xlfn.XLOOKUP("*"&RIGHT(A5,4)&"*", SYK!$E$3:$N$3, SYK!$E$31:$N$31,,2) -> 11120 | M5: 92620.452 | N5: 0.55751695 | O5: 0.44248305 | P5: =SUM(C5,F5) -> 0.34419787 | S5: FY 2022 | T5: 18449 | U5: 0.078384 | V5: 4904 | W5: 0.26581387 | X5: 8.0486 | Y5: 2036 | Z5: 11120 | AA5: 92620.452
A6: FY 2023 | B6: 20498 | C6: 0.111063 | D6: 0.639 | E6: 5520 | F6: 0.26929457 | G6: 4320 | H6: 3563 | I6: 9.2873 | J6: 3136 | K6: 124314.87 | L6: =_xlfn.XLOOKUP("*"&RIGHT(A6,4)&"*", SYK!$E$3:$N$3, SYK!$E$31:$N$31,,2) -> 9942 | M6: 113873.87 | N6: 0.59043851 | O6: 0.40956149 | P6: =SUM(C6,F6) -> 0.38035757 | S6: FY 2023 | T6: 20498 | U6: 0.111063 | V6: 5520 | W6: 0.26929457 | X6: 9.2873 | Y6: 3136 | Z6: 9942 | AA6: 113873.87
A7: FY 2024 | B7: 22595 | C7: 0.102303 | D7: 0.64461164 | E7: 6332 | F7: 0.28023899 | G7: 5092 | H7: 4205 | I7: 10.9032 | J7: 3487 | K7: 146950.07 | L7: =_xlfn.XLOOKUP("*"&RIGHT(A7,4)&"*", SYK!$E$3:$N$3, SYK!$E$31:$N$31,,2) -> 9104 | M7: 137323.07 | N7: 0.59337496 | O7: 0.40662504 | P7: =SUM(C7,F7) -> 0.38254199 | S7: FY 2024 | T7: 22595 | U7: 0.102303 | V7: 6332 | W7: 0.28023899 | X7: 10.9032 | Y7: 3487 | Z7: 9104 | AA7: 137323.07
A8: FY 2025 | B8: 25116 | C8: 0.111573 | D8: 0.653 | E8: 7269 | F8: 0.2894171 | G8: 5871 | H8: 4686 | I8: 12.1257 | J8: 4283 | K8: 146697.27 | L8: =_xlfn.XLOOKUP("*"&RIGHT(A8,4)&"*", SYK!$E$3:$N$3, SYK!$E$31:$N$31,,2) -> 11759 | M8: 134437.27 | N8: 0.59827395 | O8: 0.40172605 | P8: =SUM(C8,F8) -> 0.4009901 | S8: FY 2025 | T8: 25116 | U8: 0.111573 | V8: 7269 | W8: 0.2894171 | X8: 12.1257 | Y8: 4283 | Z8: 11759 | AA8: 134437.27
A9: FY 2026 | B9: =_xlfn.XLOOKUP("*"&A9&"*",'BBG Adj Highlights'!$C$4:$L$4,'BBG Adj Highlights'!$C$12:$L$12, , 2) -> 27317.214 | C9: =_xlfn.XLOOKUP("*"&A9&"*",'BBG Adj Highlights'!$C$4:$L$4,'BBG Adj Highlights'!$C$13:$L$13, , 2)/100 -> 0.087641913 | D9: =_xlfn.XLOOKUP("*"&RIGHT(A9,4)&"*", SYK!$E$3:$N$3, SYK!$E$27:$N$27,,2)/100 -> 0.65211765 | E9: =_xlfn.XLOOKUP("*"&A9&"*",'BBG Adj Highlights'!$C$4:$L$4,'BBG Adj Highlights'!$C$16:$L$16,,2) -> 7838.9167 | F9: =_xlfn.XLOOKUP("*"&A9&"*",'BBG Adj Highlights'!$C$4:$L$4,'BBG Adj Highlights'!$C$17:$L$17,,2) /100 -> 0.28695886 | G9: =_xlfn.XLOOKUP("*"&A9&"*",'BBG Adjusted'!$C$4:$L$4,'BBG Adjusted'!$C$65:$L$65,,2) -> 7296.6923 | H9: =_xlfn.XLOOKUP("*"&A9&"*",'BBG Adj Highlights'!$C$4:$L$4,'BBG Adj Highlights'!$C$18:$L$18,,2) -> 5814.833 | I9: =_xlfn.XLOOKUP("*"&A9&"*",'BBG Adj Highlights'!$C$4:$L$4,'BBG Adj Highlights'!$C$20:$L$20,,2) -> 15.013 | J9: =_xlfn.XLOOKUP("*"&A9&"*",'BBG Adj Highlights'!$C$4:$L$4,'BBG Adj Highlights'!$C$25:$L$25,,2) -> 5415.525 | K9: =_xlfn.XLOOKUP("*"&A9&"*",'BBG Adj Highlights'!$C$4:$L$4,'BBG Adj Highlights'!$C$10:$L$10,,2) -> 0 | L9: =_xlfn.XLOOKUP("*"&RIGHT(A9,4)&"*", SYK!$E$3:$N$3, SYK!$E$31:$N$31,,2) -> 9193.2857 | M9: =_xlfn.XLOOKUP("*"&A9&"*",'BBG Adj Highlights'!$C$4:$L$4,'BBG Adj Highlights'!$C$6:$L$6, , 2) -> 0 | N9: =IFERROR(_xlfn.XLOOKUP("*"&A9&"*",Segments!$E$3:$N$3,Segments!$E$7:$N$7,,2)/100,0) -> 0 | O9: =IFERROR(_xlfn.XLOOKUP("*"&A9&"*",Segments!$E$3:$N$3,Segments!$E$21:$N$21,,2)/100,0) -> 0 | P9: =SUM(C9,F9) -> 0.37460077 | S9: FY 2026 | T9: 27317.214 | U9: 0.087641913 | V9: 7838.9167 | W9: 0.28695886 | X9: 15.013 | Y9: 5415.525 | Z9: 9193.2857 | AA9: 0
A10: FY 2027 | B10: =_xlfn.XLOOKUP("*"&A10&"*",'BBG Adj Highlights'!$C$4:$L$4,'BBG Adj Highlights'!$C$12:$L$12, , 2) -> 29602.893 | C10: =_xlfn.XLOOKUP("*"&A10&"*",'BBG Adj Highlights'!$C$4:$L$4,'BBG Adj Highlights'!$C$13:$L$13, , 2)/100 -> 0.08367173 | D10: =_xlfn.XLOOKUP("*"&RIGHT(A10,4)&"*", SYK!$E$3:$N$3, SYK!$E$27:$N$27,,2)/100 -> 0.6546326 | E10: =_xlfn.XLOOKUP("*"&A10&"*",'BBG Adj Highlights'!$C$4:$L$4,'BBG Adj Highlights'!$C$16:$L$16,,2) -> 8626.3478 | F10: =_xlfn.XLOOKUP("*"&A10&"*",'BBG Adj Highlights'!$C$4:$L$4,'BBG Adj Highlights'!$C$17:$L$17,,2) /100 -> 0.29140219 | G10: =_xlfn.XLOOKUP("*"&A10&"*",'BBG Adjusted'!$C$4:$L$4,'BBG Adjusted'!$C$65:$L$65,,2) -> 8076.7692 | H10: =_xlfn.XLOOKUP("*"&A10&"*",'BBG Adj Highlights'!$C$4:$L$4,'BBG Adj Highlights'!$C$18:$L$18,,2) -> 6484.64 | I10: =_xlfn.XLOOKUP("*"&A10&"*",'BBG Adj Highlights'!$C$4:$L$4,'BBG Adj Highlights'!$C$20:$L$20,,2) -> 16.746 | J10: =_xlfn.XLOOKUP("*"&A10&"*",'BBG Adj Highlights'!$C$4:$L$4,'BBG Adj Highlights'!$C$25:$L$25,,2) -> 5637.65 | K10: =_xlfn.XLOOKUP("*"&A10&"*",'BBG Adj Highlights'!$C$4:$L$4,'BBG Adj Highlights'!$C$10:$L$10,,2) -> 0 | L10: =_xlfn.XLOOKUP("*"&RIGHT(A10,4)&"*", SYK!$E$3:$N$3, SYK!$E$31:$N$31,,2) -> 5874.5714 | M10: =_xlfn.XLOOKUP("*"&A10&"*",'BBG Adj Highlights'!$C$4:$L$4,'BBG Adj Highlights'!$C$6:$L$6, , 2) -> 0 | N10: =IFERROR(_xlfn.XLOOKUP("*"&A10&"*",Segments!$E$3:$N$3,Segments!$E$7:$N$7,,2)/100,0) -> 0 | O10: =IFERROR(_xlfn.XLOOKUP("*"&A10&"*",Segments!$E$3:$N$3,Segments!$E$21:$N$21,,2)/100,0) -> 0 | P10: =SUM(C10,F10) -> 0.37507392 | S10: FY 2027 | T10: 29602.893 | U10: 0.08367173 | V10: 8626.3478 | W10: 0.29140219 | X10: 16.746 | Y10: 5637.65 | Z10: 5874.5714 | AA10: 0
B12: Minimum | R12: Database Function | T12: Revenue Adj ($M) | U12: YoY Growth %
B13: =MIN(B2:B10) -> 14351 | C13: =MIN(C2:C10) -> -0.03581 | D13: =MIN(D2:D10) -> 0.631 | E13: =MIN(E2:E10) -> 3969 | F13: =MIN(F2:F10) -> 0.26581387 | G13: =MIN(G2:G10) -> 3027 | H13: =MIN(H2:H10) -> 2446 | I13: =MIN(I2:I10) -> 6.4272 | ... M13: =MIN(M2:M10) -> 0 | O13: =MIN(O2:O10) -> 0 | P13: =MIN(P2:P10) -> 0.24075609 | T13: >20000 | U13: <10%
B15: Maximum | S15: DAVERAGE EPS for Criteria Above: | T15: =DAVERAGE(Table1[#All],9,T12:U13) -> 15.8795
B16: =MAX(B2:B10) -> 29602.893 | C16: =MAX(C2:C10) -> 0.192112 | D16: =MAX(D2:D10) -> 0.659 | E16: =MAX(E2:E10) -> 8626.3478 | F16: =MAX(F2:F10) -> 0.29259608 | G16: =MAX(G2:G10) -> 8076.7692 | H16: =MAX(H2:H10) -> 6484.64 | I16: =MAX(I2:I10) -> 16.746 | ... M16: =MAX(M2:M10) -> 137323.07 | O16: =MAX(O2:O10) -> 0.55345636 | P16: =MAX(P2:P10) -> 0.47770938 | S16: DCOUNT | T16: =DCOUNTA(Table1[#All],9,T12:U13) -> 2
S17: DMAX | T17: =DMAX(Table1[#All],9,T12:U13) -> 16.746
B18: Average | S18: DMIN | T18: =DMIN(Table1[#All],9,T13:U14) -> 6.4272
B19: =AVERAGE(B2:B10) -> 21102.345 | C19: =AVERAGE(C2:C10) -> 0.091696627 | D19: =AVERAGE(D2:D10) -> 0.64581799 | E19: =AVERAGE(E2:E10) -> 5966.6961 | F19: =AVERAGE(F2:F10) -> 0.28198724 | G19: =AVERAGE(G2:G10) -> 4960.8291 | H19: =AVERAGE(H2:H10) -> 4002.7192 | I19: =AVERAGE(I2:I10) -> 10.402867 | ... M19: =AVERAGE(M2:M10) -> 83337.806 | O19: =AVERAGE(O2:O10) -> 0.34032845 | P19: =AVERAGE(P2:P10) -> 0.37368386 | S19: DSUM | T19: =DSUM(Table1[#All],9,T12:U13) -> 31.759
B21: Median | S21: SUMIFS EPS >20000 | T21: =SUMIFS(Table1[Adj EPS],Table1[Revenue Adj ($M)],">20000") -> 64.0752
B22: =MEDIAN(B2:B10) -> 20498 | C22: =MEDIAN(C2:C10) -> 0.094331 | D22: =MEDIAN(D2:D10) -> 0.64461164 | E22: =MEDIAN(E2:E10) -> 5520 | F22: =MEDIAN(F2:F10) -> 0.28559738 | G22: =MEDIAN(G2:G10) -> 4320 | H22: =MEDIAN(H2:H10) -> 3563 | I22: =MEDIAN(I2:I10) -> 9.2873 | ... M22: =MEDIAN(M2:M10) -> 92620.452 | O22: =MEDIAN(O2:O10) -> 0.40956149 | P22: =MEDIAN(P2:P10) -> 0.38035757 | S22: COUNTIFS | T22: =COUNTIFS(Table1[[#All],[Revenue Adj ($M)]], ">20000") -> 5
S23: AVERAGEIFS | T23: =AVERAGEIFS(Table1[Adj EPS],Table1[Revenue Adj ($M)],">20000") -> 12.81504
B24: Standard Deviation
B25: =_xlfn.STDEV.P(B2:B10) -> 5129.7617 | C25: =_xlfn.STDEV.P(C2:C10) -> 0.055265837 | D25: =_xlfn.STDEV.P(D2:D10) -> 0.008784942 | E25: =_xlfn.STDEV.P(E2:E10) -> 1545.3701 | F25: =_xlfn.STDEV.P(F2:F10) -> 0.0091242593 | G25: =_xlfn.STDEV.P(G2:G10) -> 1678.1631 | H25: =_xlfn.STDEV.P(H2:H10) -> 1333.2163 | I25: =_xlfn.STDEV.P(I2:I10) -> 3.3970932 | ... M25: =_xlfn.STDEV.P(M2:M10) -> 48126.634 | O25: =_xlfn.STDEV.P(O2:O10) -> 0.18700101 | P25: =_xlfn.STDEV.P(P2:P10) -> 0.058125645
B27: Year Count
B28: =SUBTOTAL(3,A2:A10) -> 9
B30: Rank (1st Cell) | C30: Percent Rank (1st Cell) | D30: Quartile (1st Cell) | E30: Frequency | F30: Correl (EBITDA:Gross Margin) | H30: NPVSolver (Set $27,317.21 to $20,498): | J30: =NPV(K30,B9) -> 20498 | K30: 0.33267706
B31: =_xlfn.RANK.AVG(B2,B2:B10,0) -> 8 | C31: =_xlfn.PERCENTRANK.EXC(C2:C10,C2) -> 0.5 | D31: =_xlfn.QUARTILE.EXC(D2:D10,1) -> 0.6385 | E31: {=FREQUENCY(E5:E10,J5:J10)} -> 0 | F31: =CORREL(F2:F7,D2:D7) -> 0.87458374
E32: 0
E33: 0
E34: 0
E35: 1
E36: 1
E37: 4

Sheet WACC Dashboard
A1: (in millions) | B1: SYK | C1: JNJ | D1: ABT | E1: BSX | F1: EW
A2: Equity Value | B2: 134437.3 | C2: 499960.4 | D2: 217578.5 | E2: 141404.1 | F2: 49504.7
A3: Preferred Equity Value | B3: 0 | C3: 0 | D3: 0 | E3: 0 | F3: 0
A4: Short-Term Debt Value | B4: 1153 | C4: 8495 | D4: 3309 | E4: 389 | F4: 24.5
A5: Long-Term Debt Value | B5: 15207 | C5: 40838 | D5: 10827 | E5: 11583 | F5: 680.9
A6: Total Capital | B6: 150797.3 | C6: 549293.4 | D6: 231714.5 | E6: 153376.1 | F6: 50210.1 | H6: % Equity | I6: {=INDEX(B7:F7,$J$9)} -> 0.892
A7: % Equity | B7: 0.892 | C7: 0.91 | D7: 0.939 | E7: 0.922 | F7: 0.986 | H7: %Preferred Equity | I7: {=INDEX(B8:F8,$J$9)} -> 0
A8: %Preferred Equity | B8: 0 | C8: 0 | D8: 0 | E8: 0 | F8: 0 | H8: % Short-Term Debt | I8: {=INDEX(B9:F9,$J$9)} -> 0.008
A9: % Short-Term Debt | B9: 0.008 | C9: 0.015 | D9: 0.014 | E9: 0.003 | F9: 0.0001 | H9: % Long-Term Debt | I9: {=INDEX(B10:F10,$J$9)} -> 0.101 | J9: 1
A10: % Long-Term Debt | B10: 0.101 | C10: 0.074 | D10: 0.047 | E10: 0.076 | F10: 0.014
A11: Beta | B11: =_xlfn.XLOOKUP(B1,'Beta Hand Calculations'!$A67:$A72,'Beta Hand Calculations'!$B67:$B72) -> 0.92827565 | C11: =_xlfn.XLOOKUP(C1,'Beta Hand Calculations'!$A67:$A72,'Beta Hand Calculations'!$B67:$B72) -> 0.32763773 | D11: =_xlfn.XLOOKUP(D1,'Beta Hand Calculations'!$A67:$A72,'Beta Hand Calculations'!$B67:$B72) -> 0.77017981 | E11: =_xlfn.XLOOKUP(E1,'Beta Hand Calculations'!$A67:$A72,'Beta Hand Calculations'!$B67:$B72) -> 0.78314866 | F11: =_xlfn.XLOOKUP(F1,'Beta Hand Calculations'!$A67:$A72,'Beta Hand Calculations'!$B67:$B72) -> 0.93461731
A12: Expected Return of Market | B12: =C13+B18 -> 0.09817
A13: Risk Free Rate | B13: {=(_xlfn.STOCKHISTORY("^TNX",TODAY(),TODAY(),2,0,1)) / 1000} -> 0.04392 | C13: 0.04317
A14: 2026 Tax Rate (%) | B14: 0.155 | C14: 0.18 | D14: 0.1626 | E14: =(BSX!M130/BSX!M123) -> 0.11678751 | F14: 0.1723
A15: Pre-Tax Cost of Debt | B15: 0.039 | C15: 0.042 | D15: 0.041 | E15: 0.048 | F15: 0.045
A16: WACC | B16: =((B2/B6)*($C$13+(B11*$B$18)))+(((B4+B5)/B6)*B15)*(1-B14) -> 0.087577961 | C16: =((C2/C6)*($C$13+(C11*$B$18)))+(((C4+C5)/C6)*C15)*(1-C14) -> 0.058787604 | D16: =((D2/D6)*($C$13+(D11*$B$18)))+(((D4+D5)/D6)*D15)*(1-D14) -> 0.082406591 | E16: =((E2/E6)*($C$13+(E11*$B$18)))+(((E4+E5)/E6)*E15)*(1-E14) -> 0.082820479 | F16: =((F2/F6)*($C$13+(F11*$B$18)))+(((F4+F5)/F6)*F15)*(1-F14) -> 0.093768561
G17: Data compiled as of March 23rd, 2026
A18: Assumed Equity Risk Premium | B18: 0.055

Sheet WACC PivotTable
A3: Row Labels | B3: Average of SYK | C3: Average of JNJ | D3: Average of ABT | E3: Average of BSX | F3: Average of EW
A4: 44197 | B4: 221.01 | C4: 163.13 | D4: 123.59 | E4: 35.44 | F4: 82.58
A5: 44228 | B5: 242.69 | C5: 158.46 | D5: 119.78 | E5: 38.78 | F5: 83.1
A6: 44256 | B6: 243.58 | C6: 164.35 | D6: 119.84 | E6: 38.65 | F6: 83.64
A7: 44287 | B7: 262.63 | C7: 162.73 | D7: 120.08 | E7: 43.6 | F7: 95.52
A8: 44317 | B8: 255.27 | C8: 169.25 | D8: 116.65 | E8: 42.55 | F8: 95.9
A9: 44348 | B9: 259.73 | C9: 164.74 | D9: 115.93 | E9: 42.76 | F9: 103.57
A10: 44378 | B10: 270.94 | C10: 172.2 | D10: 120.98 | E10: 45.6 | F10: 112.27
A11: 44409 | B11: 277.1 | C11: 173.13 | D11: 126.37 | E11: 45.15 | F11: 117.18
A12: 44440 | B12: 263.72 | C12: 161.5 | D12: 118.13 | E12: 43.39 | F12: 113.21
A13: 44470 | B13: 266.07 | C13: 162.88 | D13: 128.89 | E13: 43.13 | F13: 119.82
A14: 44501 | B14: 236.63 | C14: 155.93 | D14: 125.77 | E14: 38.07 | F14: 107.31
A15: 44531 | B15: 267.42 | C15: 171.07 | D15: 140.74 | E15: 42.48 | F15: 129.55
... A66: 46082 | B66: 328.59 | C66: 244.44 | D66: 102.67 | E66: 62.75 | F66: 80.08

Sheet Beta Hand Calculations
A1: Dates (60 Months) | B1: SYK | C1: SYK Returns | D1: JNJ | E1: JNJ Returns | F1: ABT | G1: ABT Returns | H1: BSX | I1: BSX Returns | J1: EW | K1: EW Returns | L1: S&P 500 | M1: S&P Returns
A2: 44197 | B2: {=_xlfn.STOCKHISTORY(B$1,$A$2,$A$64,2,0,1)} -> 221.01 | C2: =B3/B2-1 -> 0.098095109 | D2: {=_xlfn.STOCKHISTORY(D$1,$A$2,$A$64,2,0,1)} -> 163.13 | E2: =D3/D2-1 -> -0.028627475 | F2: {=_xlfn.STOCKHISTORY(F$1,$A$2,$A$64,2,0,1)} -> 123.59 | G2: =F3/F2-1 -> -0.030827737 | H2: {=_xlfn.STOCKHISTORY(H$1,$A$2,$A$64,2,0,1)} -> 35.44 | I2: =H3/H2-1 -> 0.094243792 | J2: {=_xlfn.STOCKHISTORY(J$1,$A$2,$A$64,2,0,1)} -> 82.58 | K2: =J3/J2-1 -> 0.0062969242 | L2: 3714.24 | M2: =L3/L2-1 -> 0.026091475
A3: 44228 | B3: 242.69 | C3: =B4/B3-1 -> 0.0036672298 | D3: 158.46 | E3: =D4/D3-1 -> 0.037170264 | F3: 119.78 | G3: =F4/F3-1 -> 0.00050091835 | H3: 38.78 | I3: =H4/H3-1 -> -0.0033522434 | J3: 83.1 | K3: =J4/J3-1 -> 0.0064981949 | L3: 3811.15 | M3: =L4/L3-1 -> 0.042438634
A4: 44256 | B4: 243.58 | C4: =B5/B4-1 -> 0.078208391 | D4: 164.35 | E4: =D5/D4-1 -> -0.0098570125 | F4: 119.84 | G4: =F5/F4-1 -> 0.0020026702 | H4: 38.65 | I4: =H5/H4-1 -> 0.12807245 | J4: 83.64 | K4: =J5/J4-1 -> 0.1420373 | L4: 3972.89 | M4: =L5/L4-1 -> 0.052425313
A5: 44287 | B5: 262.63 | C5: =B6/B5-1 -> -0.028024217 | D5: 162.73 | E5: =D6/D5-1 -> 0.040066368 | F5: 120.08 | G5: =F6/F5-1 -> -0.02856429 | H5: 43.6 | I5: =H6/H5-1 -> -0.024082569 | J5: 95.52 | K5: =J6/J5-1 -> 0.0039782245 | L5: 4181.17 | M5: =L6/L5-1 -> 0.0054865026
A6: 44317 | B6: 255.27 | C6: =B7/B6-1 -> 0.017471697 | D6: 169.25 | E6: =D7/D6-1 -> -0.026646972 | F6: 116.65 | G6: =F7/F6-1 -> -0.0061723103 | H6: 42.55 | I6: =H7/H6-1 -> 0.0049353702 | J6: 95.9 | K6: =J7/J6-1 -> 0.079979145 | L6: 4204.11 | M6: =L7/L6-1 -> 0.022213976
A7: 44348 | B7: 259.73 | C7: =B8/B7-1 -> 0.043160205 | D7: 164.74 | E7: =D8/D7-1 -> 0.045283477 | F7: 115.93 | G7: =F8/F7-1 -> 0.043560769 | H7: 42.76 | I7: =H8/H7-1 -> 0.066417212 | J7: 103.57 | K7: =J8/J7-1 -> 0.084001159 | L7: 4297.5 | M7: =L8/L7-1 -> 0.022748109
A8: 44378 | B8: 270.94 | C8: =B9/B8-1 -> 0.022735661 | D8: 172.2 | E8: =D9/D8-1 -> 0.0054006969 | F8: 120.98 | G8: =F9/F8-1 -> 0.044552819 | H8: 45.6 | I8: =H9/H8-1 -> -0.0098684211 | J8: 112.27 | K8: =J9/J8-1 -> 0.043733856 | L8: 4395.26 | M8: =L9/L8-1 -> 0.028990321
A9: 44409 | B9: 277.1 | C9: =B10/B9-1 -> -0.048285817 | D9: 173.13 | E9: =D10/D9-1 -> -0.067174955 | F9: 126.37 | G9: =F10/F9-1 -> -0.065205349 | H9: 45.15 | I9: =H10/H9-1 -> -0.038981174 | J9: 117.18 | K9: =J10/J9-1 -> -0.033879502 | L9: 4522.68 | M9: =L10/L9-1 -> -0.04756914
A10: 44440 | B10: 263.72 | C10: =B11/B10-1 -> 0.0089109662 | D10: 161.5 | E10: =D11/D10-1 -> 0.0085448916 | F10: 118.13 | G10: =F11/F10-1 -> 0.091086092 | H10: 43.39 | I10: =H11/H10-1 -> -0.0059921641 | J10: 113.21 | K10: =J11/J10-1 -> 0.058387068 | L10: 4307.54 | M10: =L11/L10-1 -> 0.069143873
A11: 44470 | B11: 266.07 | C11: =B12/B11-1 -> -0.11064757 | D11: 162.88 | E11: =D12/D11-1 -> -0.04266945 | F11: 128.89 | G11: =F12/F11-1 -> -0.024206688 | H11: 43.13 | I11: =H12/H11-1 -> -0.11731973 | J11: 119.82 | K11: =J12/J11-1 -> -0.10440661 | L11: 4605.38 | M11: =L12/L11-1 -> -0.0083337314
A12: 44501 | B12: 236.63 | C12: =B13/B12-1 -> 0.13011875 | D12: 155.93 | E12: =D13/D12-1 -> 0.09709485 | F12: 125.77 | G12: =F13/F12-1 -> 0.11902679 | H12: 38.07 | I12: =H13/H12-1 -> 0.11583924 | J12: 107.31 | K12: =J13/J12-1 -> 0.20725002 | L12: 4567 | M12: =L13/L12-1 -> 0.043612875
A13: 44531 | B13: 267.42 | C13: =B14/B13-1 -> -0.072432877 | D13: 171.07 | E13: =D14/D13-1 -> 0.0071315836 | F13: 140.74 | G13: =F14/F13-1 -> -0.094358391 | H13: 42.48 | I13: =H14/H13-1 -> 0.0098870056 | J13: 129.55 | K13: =J14/J13-1 -> -0.15708221 | L13: 4766.18 | M13: =L14/L13-1 -> -0.052585089
A14: 44562 | B14: 248.05 | C14: =B15/B14-1 -> 0.061681113 | D14: 172.29 | E14: =D15/D14-1 -> -0.044808172 | F14: 127.46 | G14: =F15/F14-1 -> -0.053663895 | H14: 42.9 | I14: =H15/H14-1 -> 0.02960373 | J14: 109.2 | K14: =J15/J14-1 -> 0.029029304 | L14: 4515.55 | M14: =L15/L14-1 -> -0.031360521
... A63: 46054 | B63: 387.46 | C63: =B64/B63-1 -> -0.15193826 | D63: 248.43 | E63: =D64/D63-1 -> -0.016060862 | F63: 116.35 | G63: =F64/F63-1 -> -0.11757628 | H63: 76.85 | I63: =H64/H63-1 -> -0.1834743 | J63: 86.47 | K63: =J64/J63-1 -> -0.073898462 | L63: 6878.88 | M63: =L64/L63-1 -> -0.05413672
A64: 46082 | B64: 328.59 | D64: 244.44 | F64: 102.67 | H64: 62.75 | J64: 80.08 | L64: 6506.48
B66: Beta Vals: | L66: I have to paste S&P values since some European stock keeps populating.
A67: =B1 -> SYK | B67: =SLOPE(C2:C63,$M$2:$M$63) -> 0.92827565
A68: =D1 -> JNJ | B68: =SLOPE(E2:E63,$M$2:$M$63) -> 0.32763773
A69: =F1 -> ABT | B69: =SLOPE(G2:G63,$M$2:$M$63) -> 0.77017981
A70: =H1 -> BSX | B70: =SLOPE(I2:I63,$M$2:$M$63) -> 0.78314866
A71: =J1 -> EW | B71: =SLOPE(K2:K63,$M$2:$M$63) -> 0.93461731
A72: =L1 -> S&P 500 | B72: =SLOPE(M2:M63,$M$2:$M$63) -> 1

Sheet SYK
A1: SYK US Equity- Company Financial (Multiple Periods)
A2: SYK US Equity Periodicity:A Currency:USD Estimate Source:BST Actual Source:Bloomberg
A3: In Millions of USD | E3: 2018 A (Rep) | F3: 2019 A (Rep) | G3: 2020 A (Rep) | H3: 2021 A (Rep) | I3: 2022 A (Rep) | J3: 2023 A (Rep) | K3: 2024 A (Rep) | L3: 2025 A (Rep) | M3: 2026 A (Fwd) | N3: 2027 A (Fwd)
A4: 12 Months Ending | B4: Field Expression | C4: Calcrt Field | D4: Segment Id | E4: 43465 | F4: 43830 | G4: 44196 | H4: 44561 | I4: 44926 | J4: 45291 | K4: 45657 | L4: 46022 | M4: 46387 | N4: 46752
A5: Highlights
A6: Adjusted Diluted EPS | B6: IS_COMP_EPS_ADJUSTED_OLD | C6: IS900 | E6: 7.31 | F6: 8.26 | G6: 7.43 | H6: 9.09 | I6: 9.34 | J6: 10.6 | K6: 12.19 | L6: 13.63 | M6: 15.012333 | N6: 16.776429
A7: Revenue | B7: IS_COMP_SALES | C7: IS902 | E7: 13601 | F7: 14884 | G7: 14351 | H7: 17108 | I7: 18449 | J7: 20498 | K7: 22595 | L7: 25116 | M7: 27330.321 | N7: 29617.036
A8: Organic Growth (%) | B8: IS_ORGANIC_GROWTH_RATE | C8: IS950 | E8: 7.9 | F8: 8.1 | G8: -4.8 | H8: 12.6 | I8: 9.7 | J8: 11.5 | K8: 10.2 | L8: 10.3 | M8: 8.7066022 | N8: 8.2261575
A10: Orthopaedics
A11: Revenue | B11: SALES_REV_TURN | C11: IS010 | D11: SEG0000608032 Segment | F11: 6409 | G11: 6006 | H11: 7570 | I11: 7556 | J11: 8335 | K11: 9077 | L11: 9469 | M11: 10036.826 | N11: 10760.019
A12: Organic Growth (%) | B12: IS_ORGANIC_GROWTH_RATE | C12: IS950 | D12: SEG0000608032 Segment | H12: 12 | I12: 7 | J12: 11.1 | K12: 8.7 | L12: 9.5 | M12: 7.631669 | N12: 7.5633887
A13: Knees | B13: SALES_REV_TURN | C13: IS010 | D13: SEG0000173641 Segment | E13: 1701 | F13: 1815 | G13: 1567 | H13: 1848 | I13: 1997 | J13: 2273 | K13: 2447 | L13: 2656 | M13: 2840.8475 | N13: 3021.1802
A14: Hips | B14: SALES_REV_TURN | C14: IS010 | D14: SEG0000173657 Segment | E14: 1336 | F14: 1383 | G14: 1206 | H14: 1342 | I14: 1413 | J14: 1544 | K14: 1704 | L14: 1865 | M14: 1989.1261 | N14: 2109.3862
A15: Trauma & Extremities | B15: SALES_REV_TURN | C15: IS010 | D15: SEG0000173644 Segment | E15: 1580 | F15: 1639 | G15: 1722 | H15: 2664 | I15: 2807 | J15: 3147 | K15: 3507 | L15: 3948 | M15: 4317.0977 | N15: 4670.8913
A16: Spinal Implants | B16: SALES_REV_TURN | C16: IS010 | D16: SEG4388955483 Segment | I16: 733 | J16: 713 | K16: 707 | L16: 185 | M16: 24
A17: Other | B17: SALES_REV_TURN | C17: IS010 | D17: SEG0000608256 Segment | E17: 374 | F17: 415 | G17: 464 | H17: 549 | I17: 606 | J17: 658 | K17: 712 | L17: 815 | M17: 872.60132 | N17: 937.5209
A18: MedSurg & Neurotechnology
A19: Revenue | B19: SALES_REV_TURN | C19: IS010 | D19: SEG0000608020 Segment | F19: 8475 | G19: 8345 | H19: 9538 | I19: 10893 | J19: 12163 | K19: 13518 | L19: 15647 | M19: 17280.12 | N19: 18817.612
A20: Organic Growth (%) | B20: IS_ORGANIC_GROWTH_RATE | C20: IS950 | D20: SEG0000608020 Segment | H20: 13.1 | I20: 11.8 | J20: 11.8 | K20: 11.2 | L20: 10.7 | M20: 8.902267 | N20: 9.1432523
A21: Instruments | B21: SALES_REV_TURN | C21: IS010 | D21: SEG0000173634 Segment | E21: 1822 | F21: 1959 | G21: 1863 | H21: 2111 | I21: 2245 | J21: 2534 | K21: 2834 | L21: 3183 | M21: 3496.053 | N21: 3793.1494
A22: Endoscopy | B22: SALES_REV_TURN | C22: IS010 | D22: SEG0000173697 Segment | E22: 1846 | F22: 1983 | G22: 1763 | H22: 2141 | I22: 2759 | J22: 3068 | K22: 3389 | L22: 3807 | M22: 4150.364 | N22: 4500.9321
A23: Medical | B23: SALES_REV_TURN | C23: IS010 | D23: SEG0000173720 Segment | E23: 2118 | F23: 2264 | G23: 2524 | H23: 2607 | I23: 3031 | J23: 3459 | K23: 3852 | L23: 4204 | M23: 4604.4725 | N23: 5005.0768
A24: Vascular | B24: SALES_REV_TURN | C24: IS010 | D24: SEG0000608022 Segment | F24: 924 | G24: 973 | H24: 1188 | I24: 1200 | J24: 1226 | K24: 1307 | L24: 1968 | M24: 2273.4045 | N24: 2502.0556
A25: Neuro Cranial | B25: SALES_REV_TURN | C25: IS010 | D25: SEG0000608023 Segment | F25: 1059 | G25: 972 | H25: 1214 | I25: 1658 | J25: 1876 | K25: 2136 | L25: 2485 | M25: 2762.5909 | N25: 3027.7051
A27: Adjusted Gross Margin (%) | B27: IS_COMP_GROSS_MARGIN_PERCENTAGE | C27: IM092 | E27: 66 | F27: 65.9 | G27: 63.8 | H27: 64.1 | I27: 63.1 | J27: 63.9 | K27: 64.461164 | L27: 65.3 | M27: 65.211765 | N27: 65.46326
A28: Adjusted Operating Margin (%) | B28: CB_IS_ADJ_OPERATING_MARGIN | C28: IM731 | E28: 25.9 | F28: 26.3 | G28: 24.4 | H28: 25.6 | I28: 23.8 | J28: 24.2 | K28: 25.3 | L28: 26.3 | M28: 26.520948 | N28: 27.099139
A29: Adjusted Net Income | B29: IS_COMP_NET_INCOME_ADJUST_OLD | C29: IS903 | E29: 2779 | F29: 3139 | G29: 2827 | H29: 3474 | I29: 3571 | J29: 4066 | K29: 4700 | L29: 5267 | M29: 5813.64 | N29: 6498.84
A31: Net Debt | B31: HEADLINE_NET_DEBT | C31: F1708 | E31: 6160 | F31: 6665 | G31: 10967 | H31: 9460 | I31: 11120 | J31: 9942 | K31: 9104 | L31: 11759 | M31: 9193.2857 | N31: 5874.5714
A32: Free Cash Flow | B32: CF_FREE_CASH_FLOW | C32: RR008 | E32: 2038 | F32: 1542 | G32: 2790 | H32: 2738 | I32: 2036 | J32: 3136 | K32: 3487 | L32: 4283 | M32: 5415.5254 | N32: 5637.6501
A34: Company Operating Metrics
A36: Company-Level Industry Statistics
A37: Sales Change - Acquisitions (%) | B37: IS_PCT_SALES_CHANGE_ACQUIS | C37: IM764 | E37: 1.9 | F37: 2.6 | G37: 1.2 | H37: 5.5 | I37: 1.3 | J37: 0.1 | K37: 0.5 | L37: 0.4 | M37: -0.16498594 | N37: 0
A39: Balance Sheet & Cash Flow Metrics
A40: Cash Conversion Cycle | B40: CASH_CONVERSION_CYCLE | C40: RR798 | E40: 232.78489 | F40: 226.59734 | G40: 248.33295 | H40: 204.03155 | I40: 197.86375 | J40: 217.53561 | K40: 206.26117 | L40: 195.44023
A41: Days Sales Outstanding | B41: ACCT_RCV_DAYS | C41: RR159 | E41: 60.784134 | F41: 64.066279 | G41: 71.333148 | H41: 61.05024 | I41: 65.159494 | J41: 65.261245 | K41: 62.78451 | L41: 58.319199 | N41: 62.381673
A43: Business Breakdown
A44: Orthopaedics
A45: Revenue | B45: SALES_REV_TURN | C45: IS010 | D45: SEG0000608032 Segment | F45: 6409 | G45: 6006 | H45: 7570 | I45: 7556 | J45: 8335 | K45: 9077 | L45: 9469 | M45: 10036.826 | N45: 10760.019
A46: Constant Currency Growth (%) | B46: REVENUE_GROWTH_CC_1_YR | C46: M0025 | D46: SEG0000608032 Segment | G46: -6.4 | H46: 24.8 | I46: 7 | J46: 10.9 | K46: 9.4 | L46: 3.8 | M46: 6.2311649 | N46: 7.6879715
A47: Organic Growth (%) | B47: IS_ORGANIC_GROWTH_RATE | C47: IS950 | D47: SEG0000608032 Segment | H47: 12 | I47: 7 | J47: 11.1 | K47: 8.7 | L47: 9.5 | M47: 7.631669 | N47: 7.5633887
...

Sheet BBG Adj Highlights
A2: Stryker Corp (SYK US) - BBG Adj Highlights
A4: In Millions of USD | C4: FY 2019 | D4: FY 2020 | E4: FY 2021 | F4: FY 2022 | G4: FY 2023 | H4: FY 2024 | I4: FY 2025 | J4: Current/LTM | K4: FY 2026 Est | L4: FY 2027 Est
A5: 12 Months Ending | C5: 12/31/2019 | D5: 12/31/2020 | E5: 12/31/2021 | F5: 12/31/2022 | G5: 12/31/2023 | H5: 12/31/2024 | I5: 12/31/2025 | J5: 12/31/2025 | K5: 12/31/2026 | L5: 12/31/2027
A6: Market Capitalization | B6: HISTORICAL_MARKET_CAP | C6: 78638.306 | D6: 92184.279 | E6: 100963 | F6: 92620.452 | G6: 113873.87 | H6: 137323.07 | I6: 134437.27 | J6: 131583.67
A7: - Cash & Equivalents | B7: CASH_AND_MARKETABLE_SECURITIES | C7: 4425 | D7: 3024 | E7: 3019 | F7: 1928 | G7: 3053 | H7: 4493 | I7: 4100 | J7: 4100
A8: + Preferred & Other | B8: PFD_EQTY_MINORTY_INTEREST | C8: 0 | D8: 0 | E8: 0 | F8: 0 | G8: 0 | H8: 0 | I8: 0 | J8: 0
A9: + Total Debt | B9: SHORT_AND_LONG_TERM_DEBT | C9: 11477 | D9: 14425 | E9: 12901 | F9: 13526 | G9: 13494 | H9: 14120 | I9: 16360 | J9: 16360
A10: Enterprise Value | B10: ENTERPRISE_VALUE | C10: 85690.306 | D10: 103585.28 | E10: 110845 | F10: 104218.45 | G10: 124314.87 | H10: 146950.07 | I10: 146697.27 | J10: 143843.67
A12: Revenue, Adj | B12: SALES_REV_TURN | C12: 14884 | D12: 14351 | E12: 17108 | F12: 18449 | G12: 20498 | H12: 22595 | I12: 25116 | J12: 25116 | K12: 27317.214 | L12: 29602.893
A13: Growth %, YoY | B13: SALES_GROWTH | C13: 9.4331 | D13: -3.581 | E13: 19.2112 | F13: 7.8384 | G13: 11.1063 | H13: 10.2303 | I13: 11.1573 | J13: 11.157336 | K13: 8.7641913 | L13: 8.367173
A14: Gross Profit, Adj | B14: GROSS_PROFIT | C14: 9807 | D14: 9160 | E14: 11267 | F14: 11649 | G14: 13099 | H14: 14565 | I14: 16391 | J14: 16391 | K14: 17835.409 | L14: 19399.664
A15: Margin % | B15: GROSS_PROFIT | C15: 65.889546 | D15: 63.828305 | E15: 65.858078 | F15: 63.141634 | G15: 63.903795 | H15: 64.461164 | I15: 65.261188 | J15: 65.261188 | K15: 65.29 | L15: 65.533
A16: EBITDA, Adj | B16: EBITDA | C16: 4355 | D16: 3969 | E16: 4886 | F16: 4904 | G16: 5520 | H16: 6332 | I16: 7269 | J16: 7269 | K16: 7838.9167 | L16: 8626.3478
A17: Margin % | B17: EBITDA | C17: 29.259608 | D17: 27.656609 | E17: 28.559738 | F17: 26.581387 | G17: 26.929457 | H17: 28.023899 | I17: 28.94171 | J17: 28.94171 | K17: 28.695886 | L17: 29.140219
A18: Net Income, Adj | B18: EARN_FOR_COMMON | C18: 2764 | D18: 2446 | E18: 2985 | F18: 3076 | G18: 3563 | H18: 4205 | I18: 4686 | J18: 4686 | K18: 5814.833 | L18: 6484.64
A19: Margin % | B19: EARN_FOR_COMMON | C19: 18.570277 | D19: 17.044108 | E19: 17.447978 | F19: 16.67299 | G19: 17.382184 | H19: 18.610312 | I19: 18.65743 | J19: 18.65743 | K19: 21.286332 | L19: 21.905427
A20: EPS, Adj | B20: IS_DIL_EPS_CONT_OPS | C20: 7.2726 | D20: 6.4272 | E20: 7.8022 | F20: 8.0486 | G20: 9.2873 | H20: 10.9032 | I20: 12.1257 | J20: 12.125771 | K20: 15.013 | L20: 16.746
A21: Growth %, YoY | B21: DILUTED_EPS_AFT_XO_ITEMS_GROWTH | C21: 13.3508 | D21: -11.6243 | E21: 21.3937 | F21: 3.158 | G21: 15.3899 | H21: 17.3989 | I21: 11.2132 | J21: 11.531854 | K21: 23.81096 | L21: 11.543329
A23: Cash from Operations | B23: CF_CASH_FROM_OPER | C23: 2191 | D23: 3277 | E23: 3263 | F23: 2624 | G23: 3711 | H23: 4242 | I23: 5044 | J23: 5044
A24: Capital Expenditures | B24: CAPITAL_EXPEND | C24: -649 | D24: -487 | E24: -525 | F24: -588 | G24: -575 | H24: -755 | I24: -761 | J24: -761 | K24: -833.4 | L24: -889.667
A25: Free Cash Flow | B25: CF_FREE_CASH_FLOW | C25: 1542 | D25: 2790 | E25: 2738 | F25: 2036 | G25: 3136 | H25: 3487 | I25: 4283 | J25: 4283 | K25: 5415.525 | L25: 5637.65
A26: Source: Bloomberg | C26: Right click to show data transparency (not supported for all values)

Sheet BBG Adjusted
A2: Stryker Corp (SYK US) - BBG Adjusted
A4: In Millions of USD except Per Share | C4: FY 2019 | D4: FY 2020 | E4: FY 2021 | F4: FY 2022 | G4: FY 2023 | H4: FY 2024 | I4: FY 2025 | J4: Last 12M | K4: FY 2026 Est | L4: FY 2027 Est
A5: 12 Months Ending | C5: 12/31/2019 | D5: 12/31/2020 | E5: 12/31/2021 | F5: 12/31/2022 | G5: 12/31/2023 | H5: 12/31/2024 | I5: 12/31/2025 | J5: 12/31/2025 | K5: 12/31/2026 | L5: 12/31/2027
A6: Revenue | B6: SALES_REV_TURN | C6: 14884 | D6: 14351 | E6: 17108 | F6: 18449 | G6: 20498 | H6: 22595 | I6: 25116 | J6: 25116 | K6: 27317.214 | L6: 29602.893
A7: + Sales & Services Revenue | B7: IS_SALES_AND_SERVICES_REVENUES | C7: 14884 | D7: 14351 | E7: 17108 | F7: 18449 | G7: 20498 | H7: 22595 | I7: 25116 | J7: 25116
A8: - Cost of Revenue | B8: IS_COGS_TO_FE_AND_PP_AND_G | C8: 5077 | D8: 5191 | E8: 5841 | F8: 6800 | G8: 7399 | H8: 8030 | I8: 8725 | J8: 8725
A9: + Cost of Goods & Services | B9: IS_COG_AND_SERVICES_SOLD | C9: 5077 | D9: 5191 | E9: 5841 | F9: 6800 | G9: 7399 | H9: 8030 | I9: 8725 | J9: 8725
A10: Gross Profit | B10: GROSS_PROFIT | C10: 9807 | D10: 9160 | E10: 11267 | F10: 11649 | G10: 13099 | H10: 14565 | I10: 16391 | J10: 16391 | K10: 17835.409 | L10: 19399.664
A11: + Other Operating Income | B11: IS_OTHER_OPER_INC | C11: 0 | D11: 0 | E11: 0 | F11: 0 | G11: 0 | H11: 0 | I11: 0 | J11: 0
A12: - Operating Expenses | B12: IS_OPERATING_EXPN | C12: 6363 | D12: 6133 | E12: 7504 | F12: 7892 | G12: 8779 | H12: 9473 | I12: 10520 | J12: 10520
A13: + Selling, General & Admin | B13: IS_SGA_EXPENSE | C13: 4984 | D13: 4755 | E13: 5752 | F13: 6035 | G13: 6851 | H13: 7436 | I13: 8221 | J13: 8221
A14: + Research & Development | B14: IS_OPERATING_EXPENSES_RD | C14: 915 | D14: 905 | E14: 1133 | F14: 1230 | G14: 1293 | H14: 1414 | I14: 1567 | J14: 1503
A15: + Other Operating Expense | B15: IS_OTHER_OPERATING_EXPENSES | C15: 464 | D15: 473 | E15: 619 | F15: 627 | G15: 635 | H15: 623 | I15: 732 | J15: 796
A16: Operating Income (Loss) | B16: IS_OPER_INC | C16: 3444 | D16: 3027 | E16: 3763 | F16: 3757 | G16: 4320 | H16: 5092 | I16: 5871 | J16: 5871 | K16: 7296.6923 | L16: 8076.7692
A17: - Non-Operating (Income) Loss | B17: IS_NONOP_INCOME_LOSS | C17: 151 | D17: 269 | E17: 303 | F17: 158 | G17: 215 | H17: 196 | I17: 402 | J17: 402
A18: + Interest Expense, Net | B18: IS_NET_INTEREST_EXPENSE | C18: 287 | D18: 315 | E18: 337 | F18: 337 | G18: 356 | H18: 396 | I18: 582
A19: + Interest Expense | B19: IS_INT_EXPENSE | C19: 287 | D19: 315 | E19: 337 | F19: 337 | G19: 356 | H19: 396 | I19: 582
A20: - Interest Income | B20: IS_INT_INC | C20: 0 | D20: 0 | E20: 0 | F20: 0 | G20: 0 | H20: 0 | I20: 0
A21: + Foreign Exch (Gain) Loss | B21: IS_FOREIGN_EXCH_LOSS | C21: 0 | D21: 0 | E21: 0 | F21: 0 | G21: 0 | H21: 0 | I21: 0
A22: + Other Non-Op (Income) Loss | B22: IS_OTHER_NON_OPERATING_INC_LOSS | C22: -136 | D22: -46 | E22: -34 | F22: -179 | G22: -141 | H22: -200 | I22: -180 | J22: 402
A23: Pretax Income (Loss), Adjusted | B23: PRETAX_INC | C23: 3293 | D23: 2758 | E23: 3460 | F23: 3599 | G23: 4105 | H23: 4896 | I23: 5469 | J23: 5469 | K23: 6872.739 | L23: 7680.261
A24: - Abnormal Losses (Gains) | B24: IS_ABNORMAL_ITEM | C24: 731 | D24: 804 | E24: 1179 | F24: 916 | G24: 432 | H24: 1404 | I24: 955 | J24: 955
A25: + Merger/Acquisition Expense | B25: IS_MERGER_ACQUISITION_EXPENSE | C25: 275 | D25: 242 | E25: 585 | F25: 150 | G25: 20 | H25: 154 | I25: 508 | J25: 508
A26: + Impairment of Goodwill | B26: IS_IMPAIRMENT_GOODWILL_INTANGIBL | C26: — | D26: — | E26: — | F26: 216 | G26: — | H26: 456 | I26: —
A27: + Impairment of Intangibles | B27: IS_IMPAIR_OF_INTANG_ASSETS | C27: — | D27: — | E27: — | F27: — | G27: — | H27: 521 | I27: 170 | J27: 170
A28: + Legal Settlement | B28: IS_LEGAL_LITIGATION_SETTLEMENT | C28: 168 | D28: 23 | E28: 101 | F28: 61 | G28: 110 | H28: 36 | I28: 17 | J28: 17
A29: + Restructuring | B29: IS_RESTRUCTURING_EXPENSES | C29: 226 | D29: 458 | E29: 386 | F29: 349 | G29: 206 | H29: 139 | I29: 164 | J29: 164
A30: + Other Abnormal Items | B30: IS_OTHER_ONE_TIME_ITEMS | C30: 62 | D30: 81 | E30: 107 | F30: 140 | G30: 96 | H30: 98 | I30: 96 | J30: 96
A31: Pretax Income (Loss), GAAP | B31: PRETAX_INC | C31: 2562 | D31: 1954 | E31: 2281 | F31: 2683 | G31: 3673 | H31: 3492 | I31: 4514 | J31: 4514 | K31: 6872.739 | L31: 7680.261
A32: - Income Tax Expense (Benefit) | B32: IS_INC_TAX_EXP | C32: 479 | D32: 355 | E32: 287 | F32: 325 | G32: 508 | H32: 499 | I32: 1268 | J32: 1268
A33: + Current Income Tax | B33: IS_CURRENT_INCOME_TAX_BENEFIT | C33: 353 | D33: 307 | E33: 524 | F33: 267 | G33: 714 | H33: 869 | I33: 876
A34: + Deferred Income Tax | B34: IS_DEFERRED_INCOME_TAX_BENEFIT | C34: 126 | D34: 48 | E34: -237 | F34: 58 | G34: -206 | H34: -370 | I34: 392
A35: Income (Loss) from Cont Ops | B35: IS_INC_BEF_XO_ITEM | C35: 2083 | D35: 1599 | E35: 1994 | F35: 2358 | G35: 3165 | H35: 2993 | I35: 3246 | J35: 3246 | K35: 4807.25 | L35: 5481.563
A36: - Net Extraordinary Losses (Gains) | B36: XO_GL_NET_OF_TAX | C36: 0 | D36: 0 | E36: 0 | F36: 0 | G36: 0 | H36: 0 | I36: 0 | J36: 0
A37: + Discontinued Operations | B37: IS_DISCONTINUED_OPERATIONS | C37: 0 | D37: 0 | E37: 0 | F37: 0 | G37: 0 | H37: 0 | I37: 0 | J37: 0
A38: + XO & Accounting Changes | B38: EXTRAORD_ITEMS_ACCOUNTING_CHANGS | C38: 0 | D38: 0 | E38: 0 | F38: 0 | G38: 0 | H38: 0 | I38: 0 | J38: 0
A39: Income (Loss) Incl. MI | B39: NI_INCLUDING_MINORITY_INT_RATIO | C39: 2083 | D39: 1599 | E39: 1994 | F39: 2358 | G39: 3165 | H39: 2993 | I39: 3246 | J39: 3246
A40: - Minority Interest | B40: MIN_NONCONTROL_INTEREST_CREDITS | C40: 0 | D40: 0 | E40: 0 | F40: 0 | G40: 0 | H40: 0 | I40: 0 | J40: 0
A41: Net Income, GAAP | B41: NET_INCOME | C41: 2083 | D41: 1599 | E41: 1994 | F41: 2358 | G41: 3165 | H41: 2993 | I41: 3246 | J41: 3246 | K41: 4807.25 | L41: 5481.563
A42: - Preferred Dividends | B42: IS_TOT_CASH_PFD_DVD | C42: 0 | D42: 0 | E42: 0 | F42: 0 | G42: 0 | H42: 0 | I42: 0 | J42: 0
...

Sheet BS
A2: Stryker Corp (SYK US) - Standardized
A4: In Millions of USD except Per Share | C4: FY 2016 | D4: FY 2017 | E4: FY 2018 | F4: FY 2019 | G4: FY 2020 | H4: FY 2021 | I4: FY 2022 | J4: FY 2023 | K4: FY 2024 | L4: FY 2025
A5: 12 Months Ending | C5: 12/31/2016 | D5: 12/31/2017 | E5: 12/31/2018 | F5: 12/31/2019 | G5: 12/31/2020 | H5: 12/31/2021 | I5: 12/31/2022 | J5: 12/31/2023 | K5: 12/31/2024 | L5: 12/31/2025
A6: Total Assets
A7: + Cash, Cash Equivalents & STI | B7: CASH_CASH_EQTY_STI_DETAILED | C7: 3384 | D7: 2793 | E7: 3699 | F7: 4425 | G7: 3024 | H7: 3019 | I7: 1928 | J7: 3053 | K7: 4493 | L7: 4100
A8: + Cash & Cash Equivalents | B8: BS_CASH_NEAR_CASH_ITEM | C8: 3316 | D8: 2542 | E8: 3616 | F8: 4337 | G8: 2943 | H8: 2944 | I8: 1844 | J8: 2971 | K8: 3652 | L8: 4011
A9: + ST Investments | B9: BS_MKT_SEC_OTHER_ST_INVEST | C9: 68 | D9: 251 | E9: 83 | F9: 88 | G9: 81 | H9: 75 | I9: 84 | J9: 82 | K9: 841 | L9: 89
A10: + Accounts & Notes Receiv | B10: BS_ACCT_NOTE_RCV | C10: 1967 | D10: 2198 | E10: 2332 | F10: 2893 | G10: 2701 | H10: 3022 | I10: 3565 | J10: 3765 | K10: 3987 | L10: 4039
A11: + Accounts Receivable, Net | B11: BS_ACCTS_REC_EXCL_NOTES_REC | C11: 1967 | D11: 2198 | E11: 2332 | F11: 2893 | G11: 2701 | H11: 3022 | I11: 3565 | J11: 3765 | K11: 3987 | L11: 4039
A12: + Notes Receivable, Net | B12: NOTES_RECEIVABLE | C12: 0 | D12: 0 | E12: 0 | F12: 0 | G12: 0 | H12: 0 | I12: 0 | J12: 0 | K12: 0 | L12: 0
